Workbook
Name Slicer_Account: #N/A
Name Slicer_Months__Date: #N/A

Sheet Bank_Statatement
A1: Date | B1: Month | C1: Description | D1: Amount | E1: Transaction Type
A2: 46023 | B2: Jan | C2: opening balance | D2: 520 | E2: opening balance
A3: 46029 | B3: Jan | C3: smith residence | D3: 185 | E3: income
A4: 46032 | B4: Jan | C4: north lumber supply | D4: -118.5 | E4: expense
A5: 46044 | B5: Jan | C5: johnson family | D5: 210.75 | E5: income
A6: 46047 | B6: Jan | C6: city equipment rentals | D6: -95.25 | E6: expense
A7: 46060 | B7: Feb | C7: lee property | D7: 240 | E7: income
A8: 46063 | B8: Feb | C8: metro concrete co | D8: -142.8 | E8: expense
A9: 46076 | B9: Feb | C9: davis home | D9: 165.5 | E9: income
A10: 46079 | B10: Feb | C10: reliable subcontractors | D10: -165.9 | E10: expense
A11: 46091 | B11: Mar | C11: wilson house | D11: 275.25 | E11: income
A12: 46093 | B12: Mar | C12: plumbpro supplies | D12: -132.4 | E12: expense
A13: 46108 | B13: Mar | C13: martinez residence | D13: 320.6 | E13: income
A14: 46110 | B14: Mar | C14: volt electrical supply | D14: -158.75 | E14: expense

Sheet Ledger
A3: Account Code | B3: Account | C3: Months (Date) | D3: Days (Date) | E3: Date | F3: Description | G3: Sum of Debit | H3: Sum of Credit | I3: Sum of Balance
A4: 1000 | B4: Cash | C4: Jan | D4: 1-Jan | E4: 46023 | F4: Opening Balance | G4: 520 | I4: 520
D5: 7-Jan | G5: 185 | I5: 185
D6: 10-Jan | H6: 118.5 | I6: -118.5
D7: 22-Jan | G7: 210.75 | I7: 210.75
D8: 25-Jan | H8: 95.25 | I8: -95.25
C9: Feb | G9: 405.5 | H9: 308.7 | I9: 96.8
C10: Mar | G10: 595.85 | H10: 291.15 | I10: 304.7
B11: Cash Total | G11: 1917.1 | H11: 813.6 | I11: 1103.5
A13: 1100 | B13: Accounts Receivable | C13: Jan | D13: 3-Jan | G13: 185 | I13: 185
D14: 7-Jan | H14: 185 | I14: -185
D15: 18-Jan | G15: 210.75 | I15: 210.75
D16: 22-Jan | H16: 210.75 | I16: -210.75
C17: Feb | G17: 405.5 | H17: 405.5 | I17: 0
C18: Mar | G18: 595.85 | H18: 595.85 | I18: 0
B19: Accounts Receivable Total | G19: 1397.1 | H19: 1397.1 | I19: 0
A21: 2000 | B21: Accounts Payable | C21: Jan | D21: 5-Jan | H21: 118.5 | I21: -118.5
D22: 10-Jan | G22: 118.5 | I22: 118.5
D23: 22-Jan | H23: 95.25 | I23: -95.25
D24: 25-Jan | G24: 95.25 | I24: 95.25
C25: Feb | G25: 308.7 | H25: 308.7 | I25: 0
C26: Mar | G26: 291.15 | H26: 291.15 | I26: 0
B27: Accounts Payable Total | G27: 813.6 | H27: 813.6 | I27: 0
A29: 3000 | B29: Owner Equity | C29: Jan | D29: 1-Jan | E29: 46023 | F29: Opening Balance | H29: 520 | I29: -520
B30: Owner Equity Total | H30: 520 | I30: -520
A32: 4000 | B32: Service Revenue | C32: Jan | D32: 3-Jan | H32: 185 | I32: -185
D33: 18-Jan | H33: 210.75 | I33: -210.75
C34: Feb | H34: 405.5 | I34: -405.5
C35: Mar | H35: 595.85 | I35: -595.85
B36: Service Revenue Total | H36: 1397.1 | I36: -1397.1
A38: 5000 | B38: Materials Expense | C38: Jan | D38: 5-Jan | G38: 118.5 | I38: 118.5
C39: Feb | G39: 142.8 | I39: 142.8
C40: Mar | G40: 291.15 | I40: 291.15
B41: Materials Expense Total | G41: 552.45 | I41: 552.45
A43: 5100 | B43: Labor Expense | C43: Feb | G43: 165.9 | I43: 165.9
B44: Labor Expense Total | G44: 165.9 | I44: 165.9
A46: 5200 | B46: Equipment Expense | C46: Jan | D46: 22-Jan | G46: 95.25 | I46: 95.25
B47: Equipment Expense Total | G47: 95.25 | I47: 95.25
A49: Grand Total | G49: 4941.4 | H49: 4941.4 | I49: 0

Sheet Journal Entries
A1: Journal Entries
A2: Date | B2: Account Code | C2: Account | D2: Description | E2: JE# | F2: Debit | G2: Credit
A3: 46023 | B3: =_xlfn.XLOOKUP(Journal_Entries[[#This Row],[Account]],'Chart Of Accounts'!E:E,'Chart Of Accounts'!D:D) -> 1000 | C3: Cash | D3: Opening Balance | E3: OB | F3: 520
A4: 46023 | B4: =_xlfn.XLOOKUP(Journal_Entries[[#This Row],[Account]],'Chart Of Accounts'!E:E,'Chart Of Accounts'!D:D) -> 3000 | C4: Owner Equity | D4: Opening Balance | E4: OB | G4: 520
A5: 46025 | B5: =_xlfn.XLOOKUP(Journal_Entries[[#This Row],[Account]],'Chart Of Accounts'!E:E,'Chart Of Accounts'!D:D) -> 1100 | C5: Accounts Receivable | D5: Smith Residence | E5: 1 | F5: 185
A6: 46025 | B6: =_xlfn.XLOOKUP(Journal_Entries[[#This Row],[Account]],'Chart Of Accounts'!E:E,'Chart Of Accounts'!D:D) -> 4000 | C6: Service Revenue | D6: Smith Residence Home Addition | E6: 1 | G6: 185
A7: 46027 | B7: =_xlfn.XLOOKUP(Journal_Entries[[#This Row],[Account]],'Chart Of Accounts'!E:E,'Chart Of Accounts'!D:D) -> 2000 | C7: Accounts Payable | D7: North Star Lumber Supply | E7: 2 | G7: 118.5
A8: 46027 | B8: =_xlfn.XLOOKUP(Journal_Entries[[#This Row],[Account]],'Chart Of Accounts'!E:E,'Chart Of Accounts'!D:D) -> 5000 | C8: Materials Expense | D8: Lumber Supply | E8: 2 | F8: 118.5
A9: 46029 | B9: =_xlfn.XLOOKUP(Journal_Entries[[#This Row],[Account]],'Chart Of Accounts'!E:E,'Chart Of Accounts'!D:D) -> 1000 | C9: Cash | D9: Smith Residence Payment | E9: 3 | F9: 185
A10: 46029 | B10: 1100 | C10: Accounts Receivable | D10: Smith Residence | E10: 3 | G10: 185
A11: 46032 | B11: 1000 | C11: Cash | D11: Payment To North Star Lumber Supply | E11: 4 | G11: 118.5
A12: 46032 | B12: =_xlfn.XLOOKUP(Journal_Entries[[#This Row],[Account]],'Chart Of Accounts'!E:E,'Chart Of Accounts'!D:D) -> 2000 | C12: Accounts Payable | D12: North Star Lumber Supply | E12: 4 | F12: 118.5
A13: 46040 | B13: =_xlfn.XLOOKUP(Journal_Entries[[#This Row],[Account]],'Chart Of Accounts'!E:E,'Chart Of Accounts'!D:D) -> 1100 | C13: Accounts Receivable | D13: Johnson Family | E13: 5 | F13: 210.75
A14: 46040 | B14: =_xlfn.XLOOKUP(Journal_Entries[[#This Row],[Account]],'Chart Of Accounts'!E:E,'Chart Of Accounts'!D:D) -> 4000 | C14: Service Revenue | D14: Johnson Family Bathroom Remodel | E14: 5 | G14: 210.75
A15: 46044 | B15: =_xlfn.XLOOKUP(Journal_Entries[[#This Row],[Account]],'Chart Of Accounts'!E:E,'Chart Of Accounts'!D:D) -> 1000 | C15: Cash | D15: Johnson Family Payment | E15: 6 | F15: 210.75
A16: 46044 | B16: =_xlfn.XLOOKUP(Journal_Entries[[#This Row],[Account]],'Chart Of Accounts'!E:E,'Chart Of Accounts'!D:D) -> 1100 | C16: Accounts Receivable | D16: Johnson Family | E16: 6 | G16: 210.75
A17: 46044 | B17: =_xlfn.XLOOKUP(Journal_Entries[[#This Row],[Account]],'Chart Of Accounts'!E:E,'Chart Of Accounts'!D:D) -> 2000 | C17: Accounts Payable | D17: City Equipment Rentals | E17: 7 | G17: 95.25
A18: 46044 | B18: =_xlfn.XLOOKUP(Journal_Entries[[#This Row],[Account]],'Chart Of Accounts'!E:E,'Chart Of Accounts'!D:D) -> 5200 | C18: Equipment Expense | D18: Equipment Rentals | E18: 7 | F18: 95.25
A19: 46047 | B19: =_xlfn.XLOOKUP(Journal_Entries[[#This Row],[Account]],'Chart Of Accounts'!E:E,'Chart Of Accounts'!D:D) -> 1000 | C19: Cash | D19: Payment To City Equipment Rentals | E19: 8 | G19: 95.25
A20: 46047 | B20: =_xlfn.XLOOKUP(Journal_Entries[[#This Row],[Account]],'Chart Of Accounts'!E:E,'Chart Of Accounts'!D:D) -> 2000 | C20: Accounts Payable | D20: City Equipment Rentals | E20: 8 | F20: 95.25
A21: 46057 | B21: =_xlfn.XLOOKUP(Journal_Entries[[#This Row],[Account]],'Chart Of Accounts'!E:E,'Chart Of Accounts'!D:D) -> 1100 | C21: Accounts Receivable | D21: Lee Property | E21: 9 | F21: 240
A22: 46057 | B22: =_xlfn.XLOOKUP(Journal_Entries[[#This Row],[Account]],'Chart Of Accounts'!E:E,'Chart Of Accounts'!D:D) -> 4000 | C22: Service Revenue | D22: Lee Property Kitchen Upgrade | E22: 9 | G22: 240
A23: 46059 | B23: =_xlfn.XLOOKUP(Journal_Entries[[#This Row],[Account]],'Chart Of Accounts'!E:E,'Chart Of Accounts'!D:D) -> 2000 | C23: Accounts Payable | D23: Metro Concrete Co | E23: 10 | G23: 142.8
A24: 46059 | B24: =_xlfn.XLOOKUP(Journal_Entries[[#This Row],[Account]],'Chart Of Accounts'!E:E,'Chart Of Accounts'!D:D) -> 5000 | C24: Materials Expense | D24: Metro Concrete Co Materials | E24: 10 | F24: 142.8
A25: 46060 | B25: =_xlfn.XLOOKUP(Journal_Entries[[#This Row],[Account]],'Chart Of Accounts'!E:E,'Chart Of Accounts'!D:D) -> 1000 | C25: Cash | D25: Lee Property Payment | E25: 11 | F25: 240
A26: 46060 | B26: =_xlfn.XLOOKUP(Journal_Entries[[#This Row],[Account]],'Chart Of Accounts'!E:E,'Chart Of Accounts'!D:D) -> 1100 | C26: Accounts Receivable | D26: Lee Property | E26: 11 | G26: 240
A27: 46063 | B27: =_xlfn.XLOOKUP(Journal_Entries[[#This Row],[Account]],'Chart Of Accounts'!E:E,'Chart Of Accounts'!D:D) -> 1000 | C27: Cash | D27: Payment To City Equipment Rentals | E27: 12 | G27: 142.8
A28: 46063 | B28: =_xlfn.XLOOKUP(Journal_Entries[[#This Row],[Account]],'Chart Of Accounts'!E:E,'Chart Of Accounts'!D:D) -> 2000 | C28: Accounts Payable | D28: Metro Concrete Co | E28: 12 | F28: 142.8
A29: 46073 | B29: =_xlfn.XLOOKUP(Journal_Entries[[#This Row],[Account]],'Chart Of Accounts'!E:E,'Chart Of Accounts'!D:D) -> 1100 | C29: Accounts Receivable | D29: Davis Home | E29: 13 | F29: 165.5
A30: 46073 | B30: =_xlfn.XLOOKUP(Journal_Entries[[#This Row],[Account]],'Chart Of Accounts'!E:E,'Chart Of Accounts'!D:D) -> 4000 | C30: Service Revenue | D30: Davis Home Roof Repair | E30: 13 | G30: 165.5
A31: 46076 | B31: =_xlfn.XLOOKUP(Journal_Entries[[#This Row],[Account]],'Chart Of Accounts'!E:E,'Chart Of Accounts'!D:D) -> 1000 | C31: Cash | D31: Davis Home Payment | E31: 14 | F31: 165.5
A32: 46076 | B32: =_xlfn.XLOOKUP(Journal_Entries[[#This Row],[Account]],'Chart Of Accounts'!E:E,'Chart Of Accounts'!D:D) -> 1100 | C32: Accounts Receivable | D32: Davis Home | E32: 14 | G32: 165.5
A33: 46078 | B33: =_xlfn.XLOOKUP(Journal_Entries[[#This Row],[Account]],'Chart Of Accounts'!E:E,'Chart Of Accounts'!D:D) -> 2000 | C33: Accounts Payable | D33: Reliable Subcontractors | E33: 15 | G33: 165.9
A34: 46078 | B34: =_xlfn.XLOOKUP(Journal_Entries[[#This Row],[Account]],'Chart Of Accounts'!E:E,'Chart Of Accounts'!D:D) -> 5100 | C34: Labor Expense | D34: Reliable Subcontractors Labor | E34: 15 | F34: 165.9
A35: 46079 | B35: =_xlfn.XLOOKUP(Journal_Entries[[#This Row],[Account]],'Chart Of Accounts'!E:E,'Chart Of Accounts'!D:D) -> 1000 | C35: Cash | D35: Payment to Reliable Subcontractors | E35: 16 | G35: 165.9
A36: 46079 | B36: =_xlfn.XLOOKUP(Journal_Entries[[#This Row],[Account]],'Chart Of Accounts'!E:E,'Chart Of Accounts'!D:D) -> 2000 | C36: Accounts Payable | D36: Reliable Subcontractors | E36: 16 | F36: 165.9
A37: 46086 | B37: =_xlfn.XLOOKUP(Journal_Entries[[#This Row],[Account]],'Chart Of Accounts'!E:E,'Chart Of Accounts'!D:D) -> 1100 | C37: Accounts Receivable | D37: Wilson House | E37: 17 | F37: 275.25
A38: 46086 | B38: =_xlfn.XLOOKUP(Journal_Entries[[#This Row],[Account]],'Chart Of Accounts'!E:E,'Chart Of Accounts'!D:D) -> 4000 | C38: Service Revenue | D38: Wilson House Deck Construction | E38: 17 | G38: 275.25
A39: 46089 | B39: =_xlfn.XLOOKUP(Journal_Entries[[#This Row],[Account]],'Chart Of Accounts'!E:E,'Chart Of Accounts'!D:D) -> 2000 | C39: Accounts Payable | D39: Plumbro Supplies | E39: 18 | G39: 132.4
A40: 46089 | B40: =_xlfn.XLOOKUP(Journal_Entries[[#This Row],[Account]],'Chart Of Accounts'!E:E,'Chart Of Accounts'!D:D) -> 5000 | C40: Materials Expense | D40: Plumbro Supplies Materials | E40: 18 | F40: 132.4
...

Sheet Receivable_Reconcile
A1: Date | B1: Month | C1: Description | D1: Amount | E1: Transaction Type | F1: Receivable.InvoiceDate | G1: Receivable.Customer | H1: Receivable.Amount | I1: Days_To_Payment
A2: 46029 | B2: Jan | C2: smith residence | D2: 185 | E2: income | F2: 46025 | G2: smith residence | H2: 185 | I2: 4
A3: 46044 | B3: Jan | C3: johnson family | D3: 210.75 | E3: income | F3: 46040 | G3: johnson family | H3: 210.75 | I3: 4
A4: 46060 | B4: Feb | C4: lee property | D4: 240 | E4: income | F4: 46057 | G4: lee property | H4: 240 | I4: 3
A5: 46076 | B5: Feb | C5: davis home | D5: 165.5 | E5: income | F5: 46073 | G5: davis home | H5: 165.5 | I5: 3
A6: 46091 | B6: Mar | C6: wilson house | D6: 275.25 | E6: income | F6: 46086 | G6: wilson house | H6: 275.25 | I6: 5
A7: 46108 | B7: Mar | C7: martinez residence | D7: 320.6 | E7: income | F7: 46103 | G7: martinez residence | H7: 320.6 | I7: 5

Sheet Payable_Reconcile
A1: Date | B1: Month | C1: Description | D1: Amount | E1: Transaction Type | F1: Payable.InvoiceDate | G1: Payable.Vendor | H1: Payable.Amount | I1: Days_To_Payment
A2: 46032 | B2: Jan | C2: north lumber supply | D2: -118.5 | E2: expense | F2: 46027 | G2: north lumber supply | H2: -118.5 | I2: 5
A3: 46047 | B3: Jan | C3: city equipment rentals | D3: -95.25 | E3: expense | F3: 46044 | G3: city equipment rentals | H3: -95.25 | I3: 3
A4: 46063 | B4: Feb | C4: metro concrete co | D4: -142.8 | E4: expense | F4: 46059 | G4: metro concrete co | H4: -142.8 | I4: 4
A5: 46079 | B5: Feb | C5: reliable subcontractors | D5: -165.9 | E5: expense | F5: 46078 | G5: reliable subcontractors | H5: -165.9 | I5: 1
A6: 46093 | B6: Mar | C6: plumbpro supplies | D6: -132.4 | E6: expense | F6: 46089 | G6: plumbpro supplies | H6: -132.4 | I6: 4
A7: 46110 | B7: Mar | C7: volt electrical supply | D7: -158.75 | E7: expense | F7: 46106 | G7: volt electrical supply | H7: -158.75 | I7: 4

Sheet Chart Of Accounts
C2: Chart Of Accounts
C3: Category | D3: Code | E3: Sub-Category | F3: FS Order
D4: 1000 | E4: Cash | F4: 1
C5: Asset | D5: 1100 | E5: Accounts Receivable | F5: 1
C6: Liabilities | D6: 2000 | E6: Accounts Payable | F6: 2
C7: Equity | D7: 3000 | E7: Owner Equity | F7: 3
C8: Revenue | D8: 4000 | E8: Service Revenue | F8: 4
C9: Expense | D9: 5000 | E9: Materials Expense | F9: 5
D10: 5100 | E10: Labor Expense | F10: 5
D11: 5200 | E11: Equipment Expense | F11: 5

Sheet Recievable
A1: InvoiceID | B1: InvoiceDate | C1: Month | D1: Customer | E1: ProjectType | F1: Amount | G1: Status | H1: source
A2: AR-1001 | B2: 46025 | C2: Jan | D2: smith residence | E2: home addition | F2: 185 | G2: paid | H2: ar
A3: AR-1002 | B3: 46040 | C3: Jan | D3: johnson family | E3: bathroom remodel | F3: 210.75 | G3: paid | H3: ar
A4: AR-1003 | B4: 46057 | C4: Feb | D4: lee property | E4: kitchen upgrade | F4: 240 | G4: paid | H4: ar
A5: AR-1004 | B5: 46073 | C5: Feb | D5: davis home | E5: roof repair | F5: 165.5 | G5: paid | H5: ar
A6: AR-1005 | B6: 46086 | C6: Mar | D6: wilson house | E6: deck construction | F6: 275.25 | G6: paid | H6: ar
A7: AR-1006 | B7: 46103 | C7: Mar | D7: martinez residence | E7: garage build | F7: 320.6 | G7: paid | H7: ar
A8: AR-1007 | B8: 46109 | C8: Mar | D8: brown property | E8: fence installation | F8: 145.35 | G8: open | H8: ar
A9: AR-1008 | B9: 46081 | C9: Feb | D9: garcia home | E9: driveway work | F9: 130.8 | G9: open | H9: ar

Sheet Payable
A1: InvoiceID | B1: InvoiceDate | C1: Month | D1: Vendor | E1: ExpenseType | F1: Amount | G1: Status | H1: Source
A2: AP-2001 | B2: 46027 | C2: Jan | D2: north lumber supply | E2: materials | F2: -118.5 | G2: paid | H2: ap
A3: AP-2002 | B3: 46044 | C3: Jan | D3: city equipment rentals | E3: equipment | F3: -95.25 | G3: paid | H3: ap
A4: AP-2003 | B4: 46059 | C4: Feb | D4: metro concrete co | E4: materials | F4: -142.8 | G4: paid | H4: ap
A5: AP-2004 | B5: 46078 | C5: Feb | D5: reliable subcontractors | E5: labor | F5: -165.9 | G5: paid | H5: ap
A6: AP-2005 | B6: 46089 | C6: Mar | D6: plumbpro supplies | E6: materials | F6: -132.4 | G6: paid | H6: ap
A7: AP-2006 | B7: 46106 | C7: Mar | D7: volt electrical supply | E7: materials | F7: -158.75 | G7: paid | H7: ap
A8: AP-2007 | B8: 46109 | C8: Mar | D8: heavy machinery co | E8: equipment | F8: -110.6 | G8: open | H8: ap
A9: AP-2008 | B9: 46081 | C9: Feb | D9: steel frame suppliers | E9: materials | F9: -126.45 | G9: open | H9: ap
